Workbook

Sheet Version Control
A1: Version Control
A2: ID | B2: Description | C2: Date | D2: Reviewer | E2: File Name | F2: Additional Comments
A3: V1 | B3: Initial Version Copyright 2021-2023, CMMC Information Institute, Inc. Released under the Creative Commons CC-BY-SA license. | C3: 46051 | D3: G. Lazo | E3: 20250130_AGL_v2023-02a-far-and-above-and-nist-sp-800-171-self-assessment-dod-score-tool | F3: Source: https://cmmcinfo.org/home/cmmc-info-tools/maturity-level-1-gap-assessment-tool/
A4: V2 | B4: Updated to include version tracking documentation and re-branded for AirGap Labs | C4: 46053 | D4: G. Lazo | E4: 20260131_AGLv2_v2023-02a-far-and-above-and-nist-sp-800-171-self-assessment-dod-score-tool | F4: Internal version:

Sheet Introduction
G1: Welcome! This Tool is designed to provide guidance to government contractors who handle Controlled Unclassified Information as they try to meet the requirements in NIST SP 800-171. The Tool organizes the 800-171 requirements using the FAR and Above program's 5-stage approach, providing contractors a step-by-step path for their compliance journey. The Tool allows you to perform a self-assessment, record the results, and create Plans of Action and Milestones ("POA&Ms") for requirements that are not met. This Tool also automatically calculates both the FAR and Above and DoD Assessment Methodology scores (also called the SPRS score) based on the self-assessment results. This Tool will be most beneficial to small businesses with a limited number of employees and a small IT infrastructure. As the organization grows, we suggest migrating to a more robust platform, like FutureFeed (https://www.FutureFeed.co), to better build and manage your cybersecurity and compliance programs. FutureFeed is a sponsor of the CMMC Information Institute.
G4: This Tool was created through the generous support of the CMMC Information Institute's donors and sponsors. Please click here to make a tax-deductable donation to the Institute. Even small donations help us offset the cost of providing valuable resources like this Tool. If you are interested in sponsoring the Institute, please contact us at info@cmmcinfo.org.
G5: This tool is updated periodically with feature enhancements, bug fixes, and other changes. Be sure to register for our newsletter so that we can alert you when changes are made.
A6: THIS TOOL IS PROVIDED BY THE COPYRIGHT HOLDERS AND CONTRIBUTORS "AS IS" AND ANY EXPRESS OR IMPLIED WARRANTIES, INCLUDING, BUT NOT LIMITED TO, THE IMPLIED WARRANTIES OF MERCHANTABILITY AND FITNESS FOR A PARTICULAR PURPOSE ARE DISCLAIMED. IN NO EVENT SHALL THE COPYRIGHT HOLDER OR CONTRIBUTORS BE LIABLE FOR ANY DIRECT, INDIRECT, INCIDENTAL, SPECIAL, EXEMPLARY, OR CONSEQUENTIAL DAMAGES (INCLUDING, BUT NOT LIMITED TO, PROCUREMENT OF SUBSTITUTE GOODS OR SERVICES; LOSS OF USE, DATA, OR PROFITS; OR BUSINESS INTERRUPTION) HOWEVER CAUSED AND ON ANY THEORY OF LIABILITY, WHETHER IN CONTRACT, STRICT LIABILITY, OR TORT (INCLUDING NEGLIGENCE OR OTHERWISE) ARISING IN ANY WAY OUT OF THE USE OF THIS SOFTWARE, EVEN IF ADVISED OF THE POSSIBILITY OF SUCH DAMAGE. | G6: This Tool consists of several worksheets, including:
G7: Introduction - This page. It provides a basic introduction to the tool and the different worksheets.
G8: Questionnaire - Used by organizations or their Managed Services Provider, Managed Security Service Provider, Consultant, etc. to help evaluate the overall maturity of the organization's cybersecurity program. For organizations with scores below about 70 points, and those who do not handle CUI, a gap analysis and remediation that focuses on FAR and Above Phase 1 may be more appropriate due to their relative immaturity. Organizations with scores above 70 are more likely to meet most of the Phase 1 requirements and thus could benefit from performing a gap analysis against all 110 controls. Remediation of any gaps can be prioritized based on the corresponding control/requirement's order in FAR and Above. For more details, please visit https://cmmcinfo.org/2022/05/11/cmmc-gap-analysis-client-engagement-process-and-questionnaire/
G9: System Overview & SSP Preamble - Provides a template for the "front matter", or preamble of a System Security Plan ("SSP"). This worksheet collects additional, basic information which must be defined under NIST SP 800-171/CMMC. Also displays FAR and Above and SPRS scores based on your answers in the SSP - DoD SPRS & Far and Above worksheet (described below). As a reminder, this SSP is used to define the security of a "system", or collection of devices, software, people, and information. The system that is the subject of this SSP may be made up of one or more subsystems.
G10: SSP - DoD SPRS & FAR and Above - Presents the NIST SP 800-171 requirements organized in the FAR and Above Program's recommended implementation order. This is where you should record your self-assessment results. Be sure to evaluate your organization against all of the objectives defined in NIST SP 800-171A (https://csrc.nist.gov/publications/detail/sp/800-171a/final) for each requirement when you perform your self-assessment. We include a recommendation as to whether a particular requirement/objective is something a typical small or medium business is likely to be able to handle themselves ("DIY") or if it is something that should probably be outsourced ("Outsource"). In a few cases, the requirements will require a combination of outside help and company resources, and we refer to these as "Hybrid". See below for additional details.
G11: POA&Ms - Create and manage plans of action and milestones ("POA&Ms") here. POA&Ms describe how your organization will meet any requirements that are not fully implemented in the assessed system. References to the relevant control automatically appear in the POA&M list if the control is not fully implemented. You can reference NIST SP 800-53, specifically CA-5 and PM-4, for additional assistance in creating the POA&Ms. See below for additional details.
G12: The System Overview & SSP Preamble, SSP - DoD SPRS & FAR and Above, and POA&Ms worksheets are required to submit a SPRS score. As you conduct your gap assessment (on the SSP - DoD SPRS & FAR and Above worksheet), you will note that your organization is expected to have certain lists and other such information. The following worksheets help you build those lists.
G13: Privileged Accounts - NIST SP 800-171 and CMMC 2.0 require that you identify all of the "privileged accounts" in use in the system. These include administrator accounts, developer accounts, and other accounts that can change security settings, alter the operation/configuration of the system, sub-system, or component, or take other actions that impact the security of the system.
G14: Physical Location(s) Info - This is a list of all of the physical locations where FCI and/or CUI is created, processed, stored, and/or transmitted (i.e., "handled"). In some cases, your organization may decide to limit access to some physical locations to only certain employee roles. For example, if your organization has a closet where your servers are stored (i.e., a "data center"), you may limit physical access to that data center to only employees who are systems administrators to help reduce the likelihood of malicious activities. The physical locations list is referenced in the Hardware Inventory worksheet (below) to help you identify the user roles which are permitted to access the different physical locations where FCI or CUI is handled.
G15: Users Auth. to Access System - This is a list of all users who are authorized to access the system.
G16: User Roles - This is a list of all of the user roles relevant to the system. Roles are used to defined categories of users who are authorized to access certain information, take certain actions, etc. This allows the organization to more easily allocate and track authorizations as employees join the organization, change jobs within the organization, and/or leave the organization.
G17: Authorized Visitor List - A list of individuals authorized to visit the location, including whether the individual is authorized to access sensitive information (including CUI) and the area(s) the user is authorized to visit.
G18: Visitor Access Log - A log of individuals who have visited the location
... G42: For each security requirement that the organization has not fully implemented, indicate a date by which the organization currently plans to fully implement that requirement. The date farthest in the future will be used to populate the "Date When 110 Score Expected" field in the Information for SPRS Submission portion of the worksheet.
A43: Version 2023.02a
AA47: Copyright 2021-2023, CMMC Information Institute, Inc. Released under the Creative Commons CC-BY-SA license. | AG47: Although we have tried to make the Tool useful, it is being provided to you as-is, and nothing in the Tool is intended to serve as, nor does it serve as, legal or technical advice. To be clear, if you use the Tool or any of the information in it, you do so at your own risk. If you do not agree, you must not use the Tool. It's that simple.
AG48: Worksheet Listing (Be sure to scroll down for additional information, including a background of the CMMC and SPRS programs and instructions for using the worksheets to conduct a self-assessment and calculate SPRS and FAR and Above scores)

Sheet Questionnaire
A1: Client Name: | B1: Canopy Aerospace and Defense
A2: Client Point of Contact (POC) Name: | B2: Richard Bays
A3: Client POC Title: | B3: CIO
A4: Client POC E-mail Address: | B4: richard.bays@canopy-ad.com
A5: Client POC Phone Number: | B5: 909-321-2001
A6: Date Questionnaire Completed:
A7: Questionnaire Score (calculated - 0 to 107) | B7: {=SUM(C22:C45)}
A9: At how many physical locations (offices, data centers, or other facilities) does your organization handle CUI or FCI? | B9: 4
A10: How many employees do you have, and how many are authorized to access government information? | B10: 180 employees, about 50 employees have access
A11: Total employees and contractors: | B11: 180 employees and 3 contractors | F11: Need to get a count of Airgap employees
A12: Authorized to access Government Information
A13: How many accounts of the following types do you have in your organization's systems?
A14: Users | B14: 180
A15: Local Administrators | B15: 0
A16: Application
A17: Service
A18: Domain Administrator
A19: Other
A20: Do you allow employees to access your systems, including E-mail, collaboration, and cloud resources, from their personal devices (i.e., BYOD)?
A21: Can any of your employees work remotely? If so, can they work remotely using their own equipment or only organization-provided equipment?
A22: Do your organization's employees periodically receive security awareness training regarding the risks associated with their activities and any applicable policies, procedures, standards, etc. relevant to the systems they use to conduct the activities? | C22: {=IF(OR(B22=References!A28,B22=""),0,IF(B22=References!A29,3,5))}
A23: Is your staff trained to recognize and properly handle sensitive information, such as bank accounts, social security numbers, design specifications, blueprints, Federal Contract Information (“FCI”) and Controlled Unclassified Information (“CUI”)? | C23: {=IF(OR(B23="No",B23=""),0,3)}
A24: Do you have a comprehensive list of all of the types of sensitive information (including FCI, CUI by type, and non-government information) in received, created, processed, stored, and/or transmitted by your organization? (If yes, we will ask you for a copy once a nondisclosure agreement is in place) | C24: {=IF(OR(B24="No",B24=""),0,5)}
A25: Do you have a comprehensive list of all hardware (including laptops, mobile devices, workstations, servers, printers, networking equipment, “smart devices” (like TVs, Alexas, etc.)) in use by your organization? (If yes, we will ask you for a copy once a nondisclosure agreement is in place) | C25: {=IF(OR(B25="No",B25=""),0,3)}
A26: Do you have a comprehensive list of all software (including operating systems, end-user software, and drivers) installed on the organization’s equipment? (If yes, we will ask you for a copy once a nondisclosure agreement is in place) | C26: {=IF(OR(B26="No",B26=""),0,5)}
A27: Do you have a comprehensive list of all cloud resources (including E-mail, file sharing, chat, collaboration, HR, payroll, and other resources) used by the organization? (If yes, we will ask you for a copy once a nondisclosure agreement is in place) | C27: {=IF(OR(B27="No",B27=""),0,5)}
A28: Do you have a network diagram? (If yes, we will ask you for a copy once a nondisclosure agreement is in place) | C28: {=IF(OR(B28="No",B28=""),0,5)}
A29: Can you show how and where sensitive information, and in particular FCI and CUI, is received, processed, stored, and transmitted within your organization? (If yes, we will ask you for a copy once a nondisclosure agreement is in place) | C29: {=IF(OR(B29="No",B29=""),0,10)}
A30: Do you have a list of all of your employees and contractors that includes their roles? If so, have you defined which roles are authorized to handle different categories of information (e.g., CUI vs FCI)? | C30: {=IF(OR(B30=References!A32,B30=""),0,IF(B30=References!A33,3,5))}
A31: Do all of your users have administrative privileges on their local computer (i.e., they are local administrators)? | C31: {=IF(OR(B31="Yes",B31=""),0,5)}
A32: Does your organization require multifactor authentication for:
A33: Remote Administration | C33: {=IF(OR(B33="Yes",B33=""),0,5)}
A34: All user remote access | C34: {=IF(OR(B34="Yes",B34=""),0,3)}
A35: All administrator logins | C35: {=IF(OR(B35="Yes",B35=""),0,5)}
A36: All user logins | C36: {=IF(OR(B36="Yes",B36=""),0,3)}
A37: Administrator access to cloud resources | C37: {=IF(OR(B37="Yes",B37=""),0,5)}
A38: All user access to cloud resources | C38: {=IF(OR(B38="Yes",B38=""),0,3)}
A39: Does your organization deploy Wi-Fi? If so, is the Wi-Fi network part of your corporate network or external to it? | C39: {=IF(OR(B39="",B39=References!A37),0,IF(B39=References!A36,3,5))}
A40: Does your organization have an incident response plan that describes roles and responsibilities? If so, do you routinely test the plan? (If you have a plan, we will ask for a copy once a nondisclosure agreement is in place)
A41: Plan | C41: {=IF(OR(B41="Yes",B41=""),0,3)}
...

Sheet System Overview & SSP Preamble
A1: System Security Plan | E1: Additional Assessor/Preparer Notes | F1: Relevant Notes from NIST
A2: FAR and Above Score (0 to 500) [Auto-calculated] | C2: {='SSP - DoD SPRS & FAR and Above'!D1}
A3: Information for SPRS Submission | B3: SPRS Score (-203 to 110) [Auto-calculated] | C3: {=IF('SSP - DoD SPRS & FAR and Above'!O80=-1000,"No SSP, therefore an assessment could not be completed due to incomplete information and noncompliance with DFARS clause 252.204-7012. See NIST SP 800-171 3.12.4.",'SSP - DoD SPRS & FAR and Above'!B1)}
B4: Date when 110 Score Expected [Auto-calculated] | C4: N/A
B5: Prepared by (Assessor Name) | C5: Onnex AI Agency (MSP)
B6: Prepared for (Organization Name) | C6: Canopy Aerospace and Defense
B7: Date of Assessment | C7: 2026-04-17
B8: CAGE Code(s) Supported by System | C8: CANPY
B9: System Description | C9: IT systems handling Controlled Unclassified Information (CUI) in support of DoD contracts
A10: System Identification | B10: Canopy Aerospace and Defense — CMMC IT System
B11: System Categorization - Confidentiality [MUST be at least Moderate if system handles CUI] | C11: Moderate
B12: System Categorization - Integrity | C12: Moderate
B13: System Categorization - Availability | C13: Moderate
B14: System Unique Identifier | C14: CANOPY-CMMC-001
B15: Responsible Organization | C15: Name: | D15: Canopy Aerospace and Defense
C16: Address: | D16: On file with MSP
C17: Phone: | D17: On file with MSP
B18: Information Owner(s): [Government point(s) of contact responsible for providing and/or receiving CUI] | C18: Name: | D18: To Be Determined — Contracting Officer
C19: Title: | D19: Contracting Officer
C20: Office Address: | D20: N/A
C21: Work Phone: | D21: N/A
C22: E-mail Address: | D22: N/A
B23: System Owner: [Assignment of security responsibility] | C23: Name: | D23: Canopy IT Admin
C24: Title: | D24: IT Administrator
C25: Office Address: | D25: On file with MSP
C26: Work Phone: | D26: On file with MSP
C27: E-mail Address: | D27: it@canopyaerospace.com
B28: System Security Officer: | C28: Name: | D28: Canopy IT Admin
C29: Title: | D29: IT Administrator / ISSO
C30: Office Address: | D30: On file with MSP
C31: Work Phone: | D31: On file with MSP
C32: E-mail Address: | D32: it@canopyaerospace.com
B33: General Description/Purpose of the system: What is the function/purpose of the system? [Provide a short, high-level description of the function/purpose of the system]
B34: TBD — pending full system inventory
B35: System Management Functions (3.13.3b): | D35: See Security Functions defined below.
B36: Security Functions (3.1.5c): | D36: Establishing System Accounts, Configuring Access Authorizations (i.e. Permissions, Privileges), Configuring Settings for Events to be Audited, Establishing Intrusion Detection Parameters, Reviewing Audit Logs [Add Additional Relevant Functions As Necessary]
B37: Security Information | D37: Filtering Rules for Routers/Firewalls, Configuration Parameters for Security Services/Devices, Cryptographic Key Management Information, Access Control Lists, Audit Logs [Add Additional Relevant Information As Necessary]
B38: Non-Security Functions (3.1.6a, 3.13.3a): | D38: All functions/activities except the Security Functions identified above.
B39: Number of Privileged Users: [Provide the approximate number of administrators, including system administrators, database administrators, application administrators, etc.] | C39: System Administrators:
C40: Database Administrators:
...

Sheet SSP - DoD SPRS & FAR and Above
A1: SPRS Score | B1: {=110+(SUM(O89:O409)+SUM(O3:O79))} | C1: FAR and Above Score | D1: {=V323+V233+V164+V77+V3} | E1: FAR and AboveTM Phased Implementation Plan for NIST SP 800-171 and CMMC 2.0 Level 2 Compliance
A2: FAR and Above Phase | B2: FAR and Above Sort Order | C2: SMB DIY or Outsource | D2: NIST SP 800-171 Family/ CMMC Domain | E2: NIST SP 800-171 ID | F2: NIST SP 800-171 Sort Order | G2: CMMC Control | H2: DoD Score Value | I2: Security Requirement | J2: Assessment Objective | K2: DoD Comment to Assessor | L2: Description of how your organization meets the Security Requirement or Assessment Objective and Link to Evidence | M2: Implementation Status | N2: Target Implementation Completion Date | O2: Score Impact | P2: Responsible Office/Organization | T2: FAR and Above Control Score | U2: FAR and Above Raw Score | V2: FAR and Above Phase Score
A3: 1 | B3: 1.01.0 | C3: Outsource | D3: System and Communications Protection | E3: 3.13.1 | F3: 03.13.01.0 | G3: SC.L1-3.13.1 | H3: 5 | I3: Monitor, control, and protect communications (i.e., information transmitted or received by organizational systems) at the external boundaries and key internal boundaries of organizational systems. | J3: Determine if: | L3: Overall Stats Meets Partially Updates required to documentation Test required for validating controls in place Examine - Policy updates required. Interview Controls are currently being implemented. - Test - Does not pass due to policy updates and required controls in place. | M3: {=IF(AND(M4="Fully Implemented",M5="Fully Implemented",M6="Fully Implemented",M7="Fully Implemented",M8="Fully Implemented",M9="Fully Implemented",M10="Fully Implemented",M11="Fully Implemented"),"Fully Implemented","")} | O3: {=IF(AND(M4="Fully Implemented",M5="Fully Implemented",M6="Fully Implemented",M7="Fully Implemented",M8="Fully Implemented",M9="Fully Implemented",M10="Fully Implemented",M11="Fully Implemented"),0,-1*H3)} | T3: {=IF(O3=0,H3,0)} | U3: {=SUM(T3:T76)} | V3: {=IF(U3=SUM(H3:H76),100,U3)}
A4: 1 | B4: 1.01.a | C4: Outsource | D4: System and Communications Protection | E4: 3.13.1[a] | F4: 03.13.01.a | G4: SC.L1-3.13.1 | J4: the external system boundary is defined. | K4: Meets Partially | L4: See the following document for details. 20260303_2023_CMMC_SC_L2-3.13.1_Assessment_by_AO Canopy-Azure-Ref-Arch Hera Network Diagrams 11-20-2025.pdf Hera All Sites IP Subnets-11-15-2025 | M4: Implementation Begun
A5: 1 | B5: 1.01.b | C5: Outsource | D5: System and Communications Protection | E5: 3.13.1[b] | F5: 03.13.01.b | G5: SC.L1-3.13.1 | J5: key internal system boundaries are defined. | K5: Meets Partially | L5: See the following document for details. 20260303_2023_CMMC_SC_L2-3.13.1_Assessment_by_AO | M5: Implementation Begun
A6: 1 | B6: 1.01.c | C6: Outsource | D6: System and Communications Protection | E6: 3.13.1[c] | F6: 03.13.01.c | G6: SC.L1-3.13.1 | J6: communications are monitored at the external system boundary. | K6: Meets Partially | L6: See the following document for details. 20260303_2023_CMMC_SC_L2-3.13.1_Assessment_by_AO | M6: Implementation Begun
A7: 1 | B7: 1.01.d | C7: Outsource | D7: System and Communications Protection | E7: 3.13.1[d] | F7: 03.13.01.d | G7: SC.L1-3.13.1 | J7: communications are monitored at key internal boundaries. | K7: Meets Partially | L7: See the following document for details. 20260303_2023_CMMC_SC_L2-3.13.1_Assessment_by_AO | M7: Implementation Begun
A8: 1 | B8: 1.01.e | C8: Outsource | D8: System and Communications Protection | E8: 3.13.1[e] | F8: 03.13.01.e | G8: SC.L1-3.13.1 | J8: communications are controlled at the external system boundary. | K8: Meets Partially | L8: See the following document for details. 20260303_2023_CMMC_SC_L2-3.13.1_Assessment_by_AO | M8: Implementation Begun
A9: 1 | B9: 1.01.f | C9: Outsource | D9: System and Communications Protection | E9: 3.13.1[f] | F9: 03.13.01.f | G9: SC.L1-3.13.1 | J9: communications are controlled at key internal boundaries. | K9: Meets Partially | L9: See the following document for details. 20260303_2023_CMMC_SC_L2-3.13.1_Assessment_by_AO | M9: Implementation Begun
A10: 1 | B10: 1.01.g | C10: Outsource | D10: System and Communications Protection | E10: 3.13.1[g] | F10: 03.13.01.g | G10: SC.L1-3.13.1 | J10: communications are protected at the external system boundary. | K10: Meets Partially | L10: See the following document for details. 20260303_2023_CMMC_SC_L2-3.13.1_Assessment_by_AO | M10: Implementation Begun
A11: 1 | B11: 1.01.h | C11: Outsource | D11: System and Communications Protection | E11: 3.13.1[h] | F11: 03.13.01.h | G11: SC.L1-3.13.1 | J11: communications are protected at key internal boundaries. | K11: Meets Partially | L11: See the following document for details. 20260303_2023_CMMC_SC_L2-3.13.1_Assessment_by_AO | M11: Implementation Begun
A12: 1 | B12: 1.02.0 | C12: Hybrid | D12: System and Communications Protection | E12: 3.13.5 | F12: 03.13.05.0 | G12: SC.L1-3.13.5 | H12: 5 | I12: Implement subnetworks for publicly accessible system components that are physically or logically separated from internal networks. | J12: Determine if: | K12: [No Comment Provided] | L12: Overall Status Meets Partially Updates required to documentation Test required for validating controls in place Examine - Policy updates required. Interview Controls are currently being implemented. - Test - Does not pass due to policy updates and required controls in place. | M12: Implementation Begun | O12: {=IF(AND(M13="Fully Implemented",M14="Fully Implemented"),0,-1*H12)} | T12: {=IF(O12=0,H12,0)}
A13: 1 | B13: 1.02.a | C13: DIY | D13: System and Communications Protection | E13: 3.13.5[a] | F13: 03.13.05.a | G13: SC.L1-3.13.5 | J13: publicly accessible system components are identified. | K13: Meets Partially | L13: Request: Inventory of all exernally facing systems. See the following document for details. 20260303_2023_CMMC_SC_L2-3.13.1_Assessment_by_AO | M13: Implementation Begun
A14: 1 | B14: 1.02.b | C14: Outsource | D14: System and Communications Protection | E14: 3.13.5[b] | F14: 03.13.05.b | G14: SC.L1-3.13.5 | J14: subnetworks for publicly accessible system components are physically or logically separated from internal networks. | K14: Meets Partially | L14: See the following document for details. 20260303_2023_CMMC_SC_L2-3.13.1_Assessment_by_AO Intune GCC - MDM VPN Information Cloud authentication Cloudflare Project Documentation Firewall Information OKTA project information VLAN information / Could update | M14: Implementation Begun
A15: 1 | B15: 1.03.0 | C15: DIY | D15: Physical Protection | E15: 3.10.1 | F15: 03.10.01.0 | G15: PE.L1-3.10.1 | H15: 5 | I15: Limit physical access to organizational systems, equipment, and the respective operating environments to authorized individuals. | J15: Determine if: | K15: [No Comment Provided] | L15: Overall Status Meets Partially Updates required to documentation Test required for validating controls in place Examine - Policy updates required. Interview Controls are currently being implemented. - Test - Pending evaluation of controls, policy/procedure updates and evidence of required controls in place. Canopy A&D - 3.10 - Physical and Environmental Protection Policy Physical Security Measures -Surveillance: Surveillance cameras shall be installed at all entry points and sensitive areas to monitor access activities. -Physical Barriers: Physical barriers such as locked doors, turnstiles, and security gates shall be used to prevent unauthorized access. Safeguarding Measures at alternate work sites -Ensure all CUI is stored in locked containers, cabinets, or desks when not in use. | M15: Implementation Begun | O15: {=IF(AND(M16="Fully Implemented",M17="Fully Implemented",M18="Fully Implemented",M19="Fully Implemented"),0,-1*H15)} | T15: {=IF(O15=0,H15,0)}
A16: 1 | B16: 1.03.a | C16: DIY | D16: Physical Protection | E16: 3.10.1[a] | F16: 03.10.01.a | G16: PE.L1-3.10.1 | J16: authorized individuals allowed physical access are identified. | K16: Meets Partially | L16: See the following document for details. 20260316_2252_CMMC_PE.L1-3.10.1_Assessment_by_AO | M16: Implementation Begun
A17: 1 | B17: 1.03.b | C17: DIY | D17: Physical Protection | E17: 3.10.1[b] | F17: 03.10.01.b | G17: PE.L1-3.10.1 | J17: physical access to organizational systems is limited to authorized individuals. | K17: Meets Partially | L17: See the following document for details. 20260316_2252_CMMC_PE.L1-3.10.1_Assessment_by_AO | M17: Implementation Begun
A18: 1 | B18: 1.03.c | C18: DIY | D18: Physical Protection | E18: 3.10.1[c] | F18: 03.10.01.c | G18: PE.L1-3.10.1 | J18: physical access to equipment is limited to authorized individuals. | K18: Meets Partially | L18: See the following document for details. 20260316_2252_CMMC_PE.L1-3.10.1_Assessment_by_AO | M18: Implementation Begun
A19: 1 | B19: 1.03.d | C19: DIY | D19: Physical Protection | E19: 3.10.1[d] | F19: 03.10.01.d | G19: PE.L1-3.10.1 | J19: physical access to operating environments is limited to authorized individuals. | K19: Meets Partially | L19: See the following document for details. 20260316_2252_CMMC_PE.L1-3.10.1_Assessment_by_AO | M19: Implementation Begun
A20: 1 | B20: 1.04.0 | C20: DIY | D20: Physical Protection | E20: 3.10.3 | F20: 03.10.03.0 | G20: PE.L1-3.10.3 | H20: 1 | I20: Escort visitors and monitor visitor activity. | J20: Determine if: | K20: [No Comment Provided] | L20: Overall Status Meets - Pending policy/procedure review meeting and observation of controls in place. Updates required to documentation Test required for validating controls in place Examine - Policy updates required. Interview Controls are currently being implemented. - Test - Review testing measures in place. Canopy A&D - 3.10 - Physical and Environmental Protection Policy, Page 1-4 | M20: Implementation Begun | O20: {=IF(AND(M21="Fully Implemented",M22="Fully Implemented"),0,-1*H20)} | T20: {=IF(O20=0,H20,0)}
A21: 1 | B21: 1.04.a | C21: DIY | D21: Physical Protection | E21: 3.10.3[a] | F21: 03.10.03.a | G21: PE.L1-3.10.3 | J21: visitors are escorted. | K21: Meets Partially | L21: See the following document for details. 20260322_2023_CMMC_PE.L1-3.10.3_Assessment_by_AO | M21: Implementation Begun
A22: 1 | B22: 1.04.b | C22: DIY | D22: Physical Protection | E22: 3.10.3[b] | F22: 03.10.03.b | G22: PE.L1-3.10.3 | J22: visitor activity is monitored. | K22: Meets Partially | L22: See the following document for details. 20260322_2023_CMMC_PE.L1-3.10.3_Assessment_by_AO | M22: Implementation Begun
A23: 1 | B23: 1.05.0 | C23: DIY | D23: Physical Protection | E23: 3.10.4 | F23: 03.10.04.0 | G23: PE.L1-3.10.4 | H23: 1 | I23: Maintain audit logs of physical access. | J23: Determine if audit logs of physical access are maintained. | K23: [No Comment Provided] | L23: Overall Status Meets - Pending policy/procedure review meeting and observation of controls in place. Updates required to documentation Test required for validating controls in place Examine - Policy updates required. Interview Controls are currently being implemented. - Test - Review testing measures in place. Canopy A&D - 3.10 - Physical and Environmental Protection Policy, Page 1-4 | M23: Implementation Begun | O23: {=IF(M23<>"Fully Implemented",-1*H23,0)} | T23: {=IF(O23=0,H23,0)}
A24: 1 | B24: 1.06.0 | C24: DIY | D24: Physical Protection | E24: 3.10.5 | F24: 03.10.05.0 | G24: PE.L1-3.10.5 | H24: 1 | I24: Control and manage physical access devices. | J24: Determine if: | K24: [No Comment Provided] | L24: Overall Status Meets - Pending policy/procedure review meeting and observation of controls in place. Updates required to documentation Test required for validating controls in place Examine - Policy updates required. Interview Controls are currently being implemented. - Test - Review testing measures in place. Canopy A&D - 3.10 - Physical and Environmental Protection Policy, Page 1-4 | M24: Implementation Begun | O24: {=IF(AND(OR(M25="Fully Implemented",M25="Not Permitted"),OR(M26="Fully Implemented",M26="Not Permitted"),OR(M27="Fully Implemented",M27="Not Permitted")),0,-1*H24)} | T24: {=IF(O24=0,H24,0)}
A25: 1 | B25: 1.06.a | C25: DIY | D25: Physical Protection | E25: 3.10.5[a] | F25: 03.10.05.a | G25: PE.L1-3.10.5 | J25: physical access devices are identified. | M25: Implementation Begun
A26: 1 | B26: 1.06.b | C26: DIY | D26: Physical Protection | E26: 3.10.5[b] | F26: 03.10.05.b | G26: PE.L1-3.10.5 | J26: physical access devices are controlled. | M26: Implementation Begun
A27: 1 | B27: 1.06.c | C27: DIY | D27: Physical Protection | E27: 3.10.5[c] | F27: 03.10.05.c | G27: PE.L1-3.10.5 | J27: physical access devices are managed. | M27: Implementation Begun
A28: 1 | B28: 1.07.0 | C28: DIY | D28: Media Protection | E28: 3.8.3 | F28: 03.08.03.0 | G28: MP.L1-3.8.3 | H28: 5 | I28: Sanitize or destroy system media containing CUI before disposal or release for reuse. | J28: Determine if: | K28: [No Comment Provided] | L28: Overall Status Meets - Pending policy/procedure review meeting and observation of controls in place. Updates required to documentation Test required for validating controls in place Examine - Policy updates required. Interview Controls are currently being implemented. - Test - Review testing measures in place. DOC-012 Canopy A&D - 3.8 - System Media Protection Policy.docx DOC-023 Certificate of Destruction-Sanitization.pdf | M28: {=IF(AND(M29="Fully Implemented",M30="Fully Implemented"),"Fully Implemented","")} | O28: {=IF(AND(M29="Fully Implemented",M30="Fully Implemented"),0,-1*H28)} | T28: {=IF(O28=0,H28,0)}
A29: 1 | B29: 1.07.a | C29: DIY | D29: Media Protection | E29: 3.8.3[a] | F29: 03.08.03.a | G29: MP.L1-3.8.3 | J29: system media containing CUI is sanitized or destroyed before disposal. | K29: Meets pending meeting | L29: See the following document for details. 20260322_2233_CMMC_MP.L1-3.8.3_Assessment_by_AO | M29: Implementation Begun
A30: 1 | B30: 1.07.b | C30: DIY | D30: Media Protection | E30: 3.8.3[b] | F30: 03.08.03.b | G30: MP.L1-3.8.3 | J30: system media containing CUI is sanitized before it is released for reuse. | K30: Meets pending meeting | L30: See the following document for details. 20260322_2233_CMMC_MP.L1-3.8.3_Assessment_by_AO | M30: Implementation Begun
A31: 1 | B31: 1.08.0 | C31: DIY | D31: System and Information Integrity | E31: 3.14.1 | F31: 03.14.01.0 | G31: SI.L1-3.14.1 | H31: 5 | I31: Identify, report, and correct system flaws in a timely manner. | J31: Determine if: | K31: [No Comment Provided] | L31: Overall Status - Pending policy/procedure review meeting and observation of controls in place. Updates required to documentation Test required for validating controls in place Examine - Policy updates may be required based on interviews/walkthroughs. Interview Controls are currently being implemented. - Test - Review testing measures in place. | M31: Implementation Begun | O31: {=IF(AND(M32="Fully Implemented",M33="Fully Implemented",M34="Fully Implemented",M35="Fully Implemented",M36="Fully Implemented",M37="Fully Implemented"),0,-1*H31)} | T31: {=IF(O31=0,H31,0)}
A32: 1 | B32: 1.08.a | C32: DIY | D32: System and Information Integrity | E32: 3.14.1[a] | F32: 03.14.01.a | G32: SI.L1-3.14.1 | J32: the time within which to identify system flaws is specified. | M32: Implementation Begun
A33: 1 | B33: 1.08.b | C33: DIY | D33: System and Information Integrity | E33: 3.14.1[b] | F33: 03.14.01.b | G33: SI.L1-3.14.1 | J33: system flaws are identified within the specified time frame. | M33: Implementation Begun
A34: 1 | B34: 1.08.c | C34: DIY | D34: System and Information Integrity | E34: 3.14.1[c] | F34: 03.14.01.c | G34: SI.L1-3.14.1 | J34: the time within which to report system flaws is specified. | M34: Implementation Begun
A35: 1 | B35: 1.08.d | C35: DIY | D35: System and Information Integrity | E35: 3.14.1[d] | F35: 03.14.01.d | G35: SI.L1-3.14.1 | J35: system flaws are reported within the specified time frame. | M35: Implementation Begun
A36: 1 | B36: 1.08.e | C36: DIY | D36: System and Information Integrity | E36: 3.14.1[e] | F36: 03.14.01.e | G36: SI.L1-3.14.1 | J36: the time within which to correct system flaws is specified. | M36: Implementation Begun
A37: 1 | B37: 1.08.f | C37: DIY | D37: System and Information Integrity | E37: 3.14.1[f] | F37: 03.14.01.f | G37: SI.L1-3.14.1 | J37: system flaws are corrected within the specified time frame. | M37: Implementation Begun
A38: 1 | B38: 1.09.0 | C38: DIY | D38: System and Information Integrity | E38: 3.14.2 | F38: 03.14.02.0 | G38: SI.L1-3.14.2 | H38: 5 | I38: Provide protection from malicious code at designated locations within organizational systems. | J38: Determine if: | K38: [No Comment Provided] | L38: Overall Status - Pending policy/procedure review meeting and observation of controls in place. Updates required to documentation Test required for validating controls in place Examine - Policy updates may be required based on interviews/walkthroughs. Interview Controls are currently being implemented. - Test - Review testing measures in place. | M38: Implementation Begun | O38: {=IF(AND(M39="Fully Implemented",M40="Fully Implemented"),0,-1*H38)} | T38: {=IF(O38=0,H38,0)}
A39: 1 | B39: 1.09.a | C39: DIY | D39: System and Information Integrity | E39: 3.14.2[a] | F39: 03.14.02.a | G39: SI.L1-3.14.2 | J39: designated locations for malicious code protection are identified. | M39: Implementation Begun
A40: 1 | B40: 1.09.b | C40: DIY | D40: System and Information Integrity | E40: 3.14.2[b] | F40: 03.14.02.b | G40: SI.L1-3.14.2 | J40: protection from malicious code at designated locations is provided. | M40: Implementation Begun
...

Sheet POA&Ms
B1: Relevant Requirement(s)/Objective(s): | C1: 3.12.2a, 3.12.2b | D1: Last Reviewed by (and on): Genemar Lazo
A2: Plans of Action and Milestones (Scroll Down for Complete List)
A3: Requirement/Objective w/Other Than Fully Addressed Status | B3: Responsible Office/Organization | C3: Resource Estimate (Funded, Unfunded, Reallocated) | D3: Initial Remediation Plan Milestones with Interim Completion Dates | E3: Changes to Milestones
A4: {=IF('SSP - DoD SPRS & FAR and Above'!M410<>"Fully Addressed",'SSP - DoD SPRS & FAR and Above'!E410&" - "&IF('SSP - DoD SPRS & FAR and Above'!I410<>"",'SSP - DoD SPRS & FAR and Above'!I410,'SSP - DoD SPRS & FAR and Above'!J410))}
A5: {=IF('SSP - DoD SPRS & FAR and Above'!M54<>"Fully Addressed",'SSP - DoD SPRS & FAR and Above'!E54&" - "&IF('SSP - DoD SPRS & FAR and Above'!I54<>"",'SSP - DoD SPRS & FAR and Above'!I54,'SSP - DoD SPRS & FAR and Above'!J54))} | B5: ISO/CISO | C5: Funded | D5: Export Entra Conditional Access & PIM/PAM approvals; provide VPN/VDI/firewall configs enforcing managed access points and FIPS-validated crypto; wireless WPA-Enterprise configs; GPO/MDM for session lock/termination. | E5: Estimate - 60 days to remediate Policies and SSP available; attach configs/logs/records as noted
A6: {=IF('SSP - DoD SPRS & FAR and Above'!M55<>"Fully Addressed",'SSP - DoD SPRS & FAR and Above'!E55&" - "&IF('SSP - DoD SPRS & FAR and Above'!I55<>"",'SSP - DoD SPRS & FAR and Above'!I55,'SSP - DoD SPRS & FAR and Above'!J55))} | B6: ISO/CISO | C6: Funded | D6: Export Entra Conditional Access & PIM/PAM approvals; provide VPN/VDI/firewall configs enforcing managed access points and FIPS-validated crypto; wireless WPA-Enterprise configs; GPO/MDM for session lock/termination. | E6: Estimate - 60 days to remediate Policies and SSP available; attach configs/logs/records as noted
A7: {=IF('SSP - DoD SPRS & FAR and Above'!M56<>"Fully Addressed",'SSP - DoD SPRS & FAR and Above'!E56&" - "&IF('SSP - DoD SPRS & FAR and Above'!I56<>"",'SSP - DoD SPRS & FAR and Above'!I56,'SSP - DoD SPRS & FAR and Above'!J56))} | B7: ISO/CISO | C7: Funded | D7: Export Entra Conditional Access & PIM/PAM approvals; provide VPN/VDI/firewall configs enforcing managed access points and FIPS-validated crypto; wireless WPA-Enterprise configs; GPO/MDM for session lock/termination. | E7: Estimate - 60 days to remediate Policies and SSP available; attach configs/logs/records as noted
A8: {=IF('SSP - DoD SPRS & FAR and Above'!M57<>"Fully Addressed",'SSP - DoD SPRS & FAR and Above'!E57&" - "&IF('SSP - DoD SPRS & FAR and Above'!I57<>"",'SSP - DoD SPRS & FAR and Above'!I57,'SSP - DoD SPRS & FAR and Above'!J57))} | B8: ISO/CISO | C8: Funded | D8: Export Entra Conditional Access & PIM/PAM approvals; provide VPN/VDI/firewall configs enforcing managed access points and FIPS-validated crypto; wireless WPA-Enterprise configs; GPO/MDM for session lock/termination. | E8: Estimate - 60 days to remediate Policies and SSP available; attach configs/logs/records as noted
A9: {=IF('SSP - DoD SPRS & FAR and Above'!M58<>"Fully Addressed",'SSP - DoD SPRS & FAR and Above'!E58&" - "&IF('SSP - DoD SPRS & FAR and Above'!I58<>"",'SSP - DoD SPRS & FAR and Above'!I58,'SSP - DoD SPRS & FAR and Above'!J58))} | B9: ISO/CISO | C9: Funded | D9: Export Entra Conditional Access & PIM/PAM approvals; provide VPN/VDI/firewall configs enforcing managed access points and FIPS-validated crypto; wireless WPA-Enterprise configs; GPO/MDM for session lock/termination. | E9: Estimate - 60 days to remediate Policies and SSP available; attach configs/logs/records as noted
A10: {=IF('SSP - DoD SPRS & FAR and Above'!M59<>"Fully Addressed",'SSP - DoD SPRS & FAR and Above'!E59&" - "&IF('SSP - DoD SPRS & FAR and Above'!I59<>"",'SSP - DoD SPRS & FAR and Above'!I59,'SSP - DoD SPRS & FAR and Above'!J59))} | B10: ISO/CISO | C10: Funded | D10: Export Entra Conditional Access & PIM/PAM approvals; provide VPN/VDI/firewall configs enforcing managed access points and FIPS-validated crypto; wireless WPA-Enterprise configs; GPO/MDM for session lock/termination. | E10: Estimate - 60 days to remediate Policies and SSP available; attach configs/logs/records as noted
A11: {=IF('SSP - DoD SPRS & FAR and Above'!M60<>"Fully Addressed",'SSP - DoD SPRS & FAR and Above'!E60&" - "&IF('SSP - DoD SPRS & FAR and Above'!I60<>"",'SSP - DoD SPRS & FAR and Above'!I60,'SSP - DoD SPRS & FAR and Above'!J60))} | B11: ISO/CISO | C11: Funded | D11: Export Entra Conditional Access & PIM/PAM approvals; provide VPN/VDI/firewall configs enforcing managed access points and FIPS-validated crypto; wireless WPA-Enterprise configs; GPO/MDM for session lock/termination. | E11: Estimate - 60 days to remediate Policies and SSP available; attach configs/logs/records as noted
A12: {=IF('SSP - DoD SPRS & FAR and Above'!M217<>"Fully Addressed",'SSP - DoD SPRS & FAR and Above'!E217&" - "&IF('SSP - DoD SPRS & FAR and Above'!I217<>"",'SSP - DoD SPRS & FAR and Above'!I217,'SSP - DoD SPRS & FAR and Above'!J217))} | B12: ISO/CISO | C12: Funded | D12: Export Entra Conditional Access & PIM/PAM approvals; provide VPN/VDI/firewall configs enforcing managed access points and FIPS-validated crypto; wireless WPA-Enterprise configs; GPO/MDM for session lock/termination. | E12: Estimate - 60 days to remediate Policies and SSP available; attach configs/logs/records as noted
A13: {=IF('SSP - DoD SPRS & FAR and Above'!M218<>"Fully Addressed",'SSP - DoD SPRS & FAR and Above'!E218&" - "&IF('SSP - DoD SPRS & FAR and Above'!I218<>"",'SSP - DoD SPRS & FAR and Above'!I218,'SSP - DoD SPRS & FAR and Above'!J218))} | B13: ISO/CISO | C13: Funded | D13: Export Entra Conditional Access & PIM/PAM approvals; provide VPN/VDI/firewall configs enforcing managed access points and FIPS-validated crypto; wireless WPA-Enterprise configs; GPO/MDM for session lock/termination. | E13: Estimate - 60 days to remediate Policies and SSP available; attach configs/logs/records as noted
A14: {=IF('SSP - DoD SPRS & FAR and Above'!M219<>"Fully Addressed",'SSP - DoD SPRS & FAR and Above'!E219&" - "&IF('SSP - DoD SPRS & FAR and Above'!I219<>"",'SSP - DoD SPRS & FAR and Above'!I219,'SSP - DoD SPRS & FAR and Above'!J219))} | B14: ISO/CISO | C14: Funded | D14: Export Entra Conditional Access & PIM/PAM approvals; provide VPN/VDI/firewall configs enforcing managed access points and FIPS-validated crypto; wireless WPA-Enterprise configs; GPO/MDM for session lock/termination. | E14: Estimate - 60 days to remediate Policies and SSP available; attach configs/logs/records as noted
A15: {=IF('SSP - DoD SPRS & FAR and Above'!M220<>"Fully Addressed",'SSP - DoD SPRS & FAR and Above'!E220&" - "&IF('SSP - DoD SPRS & FAR and Above'!I220<>"",'SSP - DoD SPRS & FAR and Above'!I220,'SSP - DoD SPRS & FAR and Above'!J220))} | B15: ISO/CISO | C15: Funded | D15: Export Entra Conditional Access & PIM/PAM approvals; provide VPN/VDI/firewall configs enforcing managed access points and FIPS-validated crypto; wireless WPA-Enterprise configs; GPO/MDM for session lock/termination. | E15: Estimate - 60 days to remediate Policies and SSP available; attach configs/logs/records as noted
A16: {=IF('SSP - DoD SPRS & FAR and Above'!M379<>"Fully Addressed",'SSP - DoD SPRS & FAR and Above'!E379&" - "&IF('SSP - DoD SPRS & FAR and Above'!I379<>"",'SSP - DoD SPRS & FAR and Above'!I379,'SSP - DoD SPRS & FAR and Above'!J379))} | B16: ISO/CISO | C16: Funded | D16: Export Entra Conditional Access & PIM/PAM approvals; provide VPN/VDI/firewall configs enforcing managed access points and FIPS-validated crypto; wireless WPA-Enterprise configs; GPO/MDM for session lock/termination. | E16: Estimate - 60 days to remediate Policies and SSP available; attach configs/logs/records as noted
A17: {=IF('SSP - DoD SPRS & FAR and Above'!M380<>"Fully Addressed",'SSP - DoD SPRS & FAR and Above'!E380&" - "&IF('SSP - DoD SPRS & FAR and Above'!I380<>"",'SSP - DoD SPRS & FAR and Above'!I380,'SSP - DoD SPRS & FAR and Above'!J380))} | B17: ISO/CISO | C17: Funded | D17: Export Entra Conditional Access & PIM/PAM approvals; provide VPN/VDI/firewall configs enforcing managed access points and FIPS-validated crypto; wireless WPA-Enterprise configs; GPO/MDM for session lock/termination. | E17: Estimate - 60 days to remediate Policies and SSP available; attach configs/logs/records as noted
A18: {=IF('SSP - DoD SPRS & FAR and Above'!M381<>"Fully Addressed",'SSP - DoD SPRS & FAR and Above'!E381&" - "&IF('SSP - DoD SPRS & FAR and Above'!I381<>"",'SSP - DoD SPRS & FAR and Above'!I381,'SSP - DoD SPRS & FAR and Above'!J381))} | B18: ISO/CISO | C18: Funded | D18: Export Entra Conditional Access & PIM/PAM approvals; provide VPN/VDI/firewall configs enforcing managed access points and FIPS-validated crypto; wireless WPA-Enterprise configs; GPO/MDM for session lock/termination. | E18: Estimate - 60 days to remediate Policies and SSP available; attach configs/logs/records as noted
A19: {=IF('SSP - DoD SPRS & FAR and Above'!M176<>"Fully Addressed",'SSP - DoD SPRS & FAR and Above'!E176&" - "&IF('SSP - DoD SPRS & FAR and Above'!I176<>"",'SSP - DoD SPRS & FAR and Above'!I176,'SSP - DoD SPRS & FAR and Above'!J176))} | B19: ISO/CISO | C19: Funded | D19: Export Entra Conditional Access & PIM/PAM approvals; provide VPN/VDI/firewall configs enforcing managed access points and FIPS-validated crypto; wireless WPA-Enterprise configs; GPO/MDM for session lock/termination. | E19: Estimate - 60 days to remediate Policies and SSP available; attach configs/logs/records as noted
A20: {=IF('SSP - DoD SPRS & FAR and Above'!M177<>"Fully Addressed",'SSP - DoD SPRS & FAR and Above'!E177&" - "&IF('SSP - DoD SPRS & FAR and Above'!I177<>"",'SSP - DoD SPRS & FAR and Above'!I177,'SSP - DoD SPRS & FAR and Above'!J177))} | B20: ISO/CISO | C20: Funded | D20: Export Entra Conditional Access & PIM/PAM approvals; provide VPN/VDI/firewall configs enforcing managed access points and FIPS-validated crypto; wireless WPA-Enterprise configs; GPO/MDM for session lock/termination. | E20: Estimate - 60 days to remediate Policies and SSP available; attach configs/logs/records as noted
A21: {=IF('SSP - DoD SPRS & FAR and Above'!M178<>"Fully Addressed",'SSP - DoD SPRS & FAR and Above'!E178&" - "&IF('SSP - DoD SPRS & FAR and Above'!I178<>"",'SSP - DoD SPRS & FAR and Above'!I178,'SSP - DoD SPRS & FAR and Above'!J178))} | B21: ISO/CISO | C21: Funded | D21: Export Entra Conditional Access & PIM/PAM approvals; provide VPN/VDI/firewall configs enforcing managed access points and FIPS-validated crypto; wireless WPA-Enterprise configs; GPO/MDM for session lock/termination. | E21: Estimate - 60 days to remediate Policies and SSP available; attach configs/logs/records as noted
A22: {=IF('SSP - DoD SPRS & FAR and Above'!M179<>"Fully Addressed",'SSP - DoD SPRS & FAR and Above'!E179&" - "&IF('SSP - DoD SPRS & FAR and Above'!I179<>"",'SSP - DoD SPRS & FAR and Above'!I179,'SSP - DoD SPRS & FAR and Above'!J179))} | B22: ISO/CISO | C22: Funded | D22: Export Entra Conditional Access & PIM/PAM approvals; provide VPN/VDI/firewall configs enforcing managed access points and FIPS-validated crypto; wireless WPA-Enterprise configs; GPO/MDM for session lock/termination. | E22: Estimate - 60 days to remediate Policies and SSP available; attach configs/logs/records as noted
A23: {=IF('SSP - DoD SPRS & FAR and Above'!M180<>"Fully Addressed",'SSP - DoD SPRS & FAR and Above'!E180&" - "&IF('SSP - DoD SPRS & FAR and Above'!I180<>"",'SSP - DoD SPRS & FAR and Above'!I180,'SSP - DoD SPRS & FAR and Above'!J180))} | B23: ISO/CISO | C23: Funded | D23: Export Entra Conditional Access & PIM/PAM approvals; provide VPN/VDI/firewall configs enforcing managed access points and FIPS-validated crypto; wireless WPA-Enterprise configs; GPO/MDM for session lock/termination. | E23: Estimate - 60 days to remediate Policies and SSP available; attach configs/logs/records as noted
A24: {=IF('SSP - DoD SPRS & FAR and Above'!M181<>"Fully Addressed",'SSP - DoD SPRS & FAR and Above'!E181&" - "&IF('SSP - DoD SPRS & FAR and Above'!I181<>"",'SSP - DoD SPRS & FAR and Above'!I181,'SSP - DoD SPRS & FAR and Above'!J181))} | B24: ISO/CISO | C24: Funded | D24: Export Entra Conditional Access & PIM/PAM approvals; provide VPN/VDI/firewall configs enforcing managed access points and FIPS-validated crypto; wireless WPA-Enterprise configs; GPO/MDM for session lock/termination. | E24: Estimate - 60 days to remediate Policies and SSP available; attach configs/logs/records as noted
A25: {=IF('SSP - DoD SPRS & FAR and Above'!M182<>"Fully Addressed",'SSP - DoD SPRS & FAR and Above'!E182&" - "&IF('SSP - DoD SPRS & FAR and Above'!I182<>"",'SSP - DoD SPRS & FAR and Above'!I182,'SSP - DoD SPRS & FAR and Above'!J182))} | B25: ISO/CISO | C25: Funded | D25: Export Entra Conditional Access & PIM/PAM approvals; provide VPN/VDI/firewall configs enforcing managed access points and FIPS-validated crypto; wireless WPA-Enterprise configs; GPO/MDM for session lock/termination. | E25: Estimate - 60 days to remediate Policies and SSP available; attach configs/logs/records as noted
A26: {=IF('SSP - DoD SPRS & FAR and Above'!M183<>"Fully Addressed",'SSP - DoD SPRS & FAR and Above'!E183&" - "&IF('SSP - DoD SPRS & FAR and Above'!I183<>"",'SSP - DoD SPRS & FAR and Above'!I183,'SSP - DoD SPRS & FAR and Above'!J183))} | B26: ISO/CISO | C26: Funded | D26: Export Entra Conditional Access & PIM/PAM approvals; provide VPN/VDI/firewall configs enforcing managed access points and FIPS-validated crypto; wireless WPA-Enterprise configs; GPO/MDM for session lock/termination. | E26: Estimate - 60 days to remediate Policies and SSP available; attach configs/logs/records as noted
A27: {=IF('SSP - DoD SPRS & FAR and Above'!M399<>"Fully Addressed",'SSP - DoD SPRS & FAR and Above'!E399&" - "&IF('SSP - DoD SPRS & FAR and Above'!I399<>"",'SSP - DoD SPRS & FAR and Above'!I399,'SSP - DoD SPRS & FAR and Above'!J399))} | B27: ISO/CISO | C27: Funded | D27: Export Entra Conditional Access & PIM/PAM approvals; provide VPN/VDI/firewall configs enforcing managed access points and FIPS-validated crypto; wireless WPA-Enterprise configs; GPO/MDM for session lock/termination. | E27: Estimate - 60 days to remediate Policies and SSP available; attach configs/logs/records as noted
A28: {=IF('SSP - DoD SPRS & FAR and Above'!M400<>"Fully Addressed",'SSP - DoD SPRS & FAR and Above'!E400&" - "&IF('SSP - DoD SPRS & FAR and Above'!I400<>"",'SSP - DoD SPRS & FAR and Above'!I400,'SSP - DoD SPRS & FAR and Above'!J400))} | B28: ISO/CISO | C28: Funded | D28: Export Entra Conditional Access & PIM/PAM approvals; provide VPN/VDI/firewall configs enforcing managed access points and FIPS-validated crypto; wireless WPA-Enterprise configs; GPO/MDM for session lock/termination. | E28: Estimate - 60 days to remediate Policies and SSP available; attach configs/logs/records as noted
A29: {=IF('SSP - DoD SPRS & FAR and Above'!M401<>"Fully Addressed",'SSP - DoD SPRS & FAR and Above'!E401&" - "&IF('SSP - DoD SPRS & FAR and Above'!I401<>"",'SSP - DoD SPRS & FAR and Above'!I401,'SSP - DoD SPRS & FAR and Above'!J401))} | B29: ISO/CISO | C29: Funded | D29: Export Entra Conditional Access & PIM/PAM approvals; provide VPN/VDI/firewall configs enforcing managed access points and FIPS-validated crypto; wireless WPA-Enterprise configs; GPO/MDM for session lock/termination. | E29: Estimate - 60 days to remediate Policies and SSP available; attach configs/logs/records as noted
A30: {=IF('SSP - DoD SPRS & FAR and Above'!M402<>"Fully Addressed",'SSP - DoD SPRS & FAR and Above'!E402&" - "&IF('SSP - DoD SPRS & FAR and Above'!I402<>"",'SSP - DoD SPRS & FAR and Above'!I402,'SSP - DoD SPRS & FAR and Above'!J402))} | B30: ISO/CISO | C30: Funded | D30: Export Entra Conditional Access & PIM/PAM approvals; provide VPN/VDI/firewall configs enforcing managed access points and FIPS-validated crypto; wireless WPA-Enterprise configs; GPO/MDM for session lock/termination. | E30: Estimate - 60 days to remediate Policies and SSP available; attach configs/logs/records as noted
A31: {=IF('SSP - DoD SPRS & FAR and Above'!M403<>"Fully Addressed",'SSP - DoD SPRS & FAR and Above'!E403&" - "&IF('SSP - DoD SPRS & FAR and Above'!I403<>"",'SSP - DoD SPRS & FAR and Above'!I403,'SSP - DoD SPRS & FAR and Above'!J403))} | B31: ISO/CISO | C31: Funded | D31: Export Entra Conditional Access & PIM/PAM approvals; provide VPN/VDI/firewall configs enforcing managed access points and FIPS-validated crypto; wireless WPA-Enterprise configs; GPO/MDM for session lock/termination. | E31: Estimate - 60 days to remediate Policies and SSP available; attach configs/logs/records as noted
A32: {=IF('SSP - DoD SPRS & FAR and Above'!M404<>"Fully Addressed",'SSP - DoD SPRS & FAR and Above'!E404&" - "&IF('SSP - DoD SPRS & FAR and Above'!I404<>"",'SSP - DoD SPRS & FAR and Above'!I404,'SSP - DoD SPRS & FAR and Above'!J404))} | B32: ISO/CISO | C32: Funded | D32: Export Entra Conditional Access & PIM/PAM approvals; provide VPN/VDI/firewall configs enforcing managed access points and FIPS-validated crypto; wireless WPA-Enterprise configs; GPO/MDM for session lock/termination. | E32: Estimate - 60 days to remediate Policies and SSP available; attach configs/logs/records as noted
A33: {=IF('SSP - DoD SPRS & FAR and Above'!M405<>"Fully Addressed",'SSP - DoD SPRS & FAR and Above'!E405&" - "&IF('SSP - DoD SPRS & FAR and Above'!I405<>"",'SSP - DoD SPRS & FAR and Above'!I405,'SSP - DoD SPRS & FAR and Above'!J405))} | B33: ISO/CISO | C33: Funded | D33: Export Entra Conditional Access & PIM/PAM approvals; provide VPN/VDI/firewall configs enforcing managed access points and FIPS-validated crypto; wireless WPA-Enterprise configs; GPO/MDM for session lock/termination. | E33: Estimate - 60 days to remediate Policies and SSP available; attach configs/logs/records as noted
A34: {=IF('SSP - DoD SPRS & FAR and Above'!M406<>"Fully Addressed",'SSP - DoD SPRS & FAR and Above'!E406&" - "&IF('SSP - DoD SPRS & FAR and Above'!I406<>"",'SSP - DoD SPRS & FAR and Above'!I406,'SSP - DoD SPRS & FAR and Above'!J406))} | B34: ISO/CISO | C34: Funded | D34: Export Entra Conditional Access & PIM/PAM approvals; provide VPN/VDI/firewall configs enforcing managed access points and FIPS-validated crypto; wireless WPA-Enterprise configs; GPO/MDM for session lock/termination. | E34: Estimate - 60 days to remediate Policies and SSP available; attach configs/logs/records as noted
A35: {=IF('SSP - DoD SPRS & FAR and Above'!M173<>"Fully Addressed",'SSP - DoD SPRS & FAR and Above'!E173&" - "&IF('SSP - DoD SPRS & FAR and Above'!I173<>"",'SSP - DoD SPRS & FAR and Above'!I173,'SSP - DoD SPRS & FAR and Above'!J173))} | B35: ISO/CISO | C35: Funded | D35: Export Entra Conditional Access & PIM/PAM approvals; provide VPN/VDI/firewall configs enforcing managed access points and FIPS-validated crypto; wireless WPA-Enterprise configs; GPO/MDM for session lock/termination. | E35: Estimate - 60 days to remediate Policies and SSP available; attach configs/logs/records as noted
A36: {=IF('SSP - DoD SPRS & FAR and Above'!M174<>"Fully Addressed",'SSP - DoD SPRS & FAR and Above'!E174&" - "&IF('SSP - DoD SPRS & FAR and Above'!I174<>"",'SSP - DoD SPRS & FAR and Above'!I174,'SSP - DoD SPRS & FAR and Above'!J174))} | B36: ISO/CISO | C36: Funded | D36: Export Entra Conditional Access & PIM/PAM approvals; provide VPN/VDI/firewall configs enforcing managed access points and FIPS-validated crypto; wireless WPA-Enterprise configs; GPO/MDM for session lock/termination. | E36: Estimate - 60 days to remediate Policies and SSP available; attach configs/logs/records as noted
A37: {=IF('SSP - DoD SPRS & FAR and Above'!M175<>"Fully Addressed",'SSP - DoD SPRS & FAR and Above'!E175&" - "&IF('SSP - DoD SPRS & FAR and Above'!I175<>"",'SSP - DoD SPRS & FAR and Above'!I175,'SSP - DoD SPRS & FAR and Above'!J175))} | B37: ISO/CISO | C37: Funded | D37: Export Entra Conditional Access & PIM/PAM approvals; provide VPN/VDI/firewall configs enforcing managed access points and FIPS-validated crypto; wireless WPA-Enterprise configs; GPO/MDM for session lock/termination. | E37: Estimate - 60 days to remediate Policies and SSP available; attach configs/logs/records as noted
A38: {=IF('SSP - DoD SPRS & FAR and Above'!M170<>"Fully Addressed",'SSP - DoD SPRS & FAR and Above'!E170&" - "&IF('SSP - DoD SPRS & FAR and Above'!I170<>"",'SSP - DoD SPRS & FAR and Above'!I170,'SSP - DoD SPRS & FAR and Above'!J170))} | B38: ISO/CISO | C38: Funded | D38: Export Entra Conditional Access & PIM/PAM approvals; provide VPN/VDI/firewall configs enforcing managed access points and FIPS-validated crypto; wireless WPA-Enterprise configs; GPO/MDM for session lock/termination. | E38: Estimate - 60 days to remediate Policies and SSP available; attach configs/logs/records as noted
A39: {=IF('SSP - DoD SPRS & FAR and Above'!M171<>"Fully Addressed",'SSP - DoD SPRS & FAR and Above'!E171&" - "&IF('SSP - DoD SPRS & FAR and Above'!I171<>"",'SSP - DoD SPRS & FAR and Above'!I171,'SSP - DoD SPRS & FAR and Above'!J171))} | B39: ISO/CISO | C39: Funded | D39: Export Entra Conditional Access & PIM/PAM approvals; provide VPN/VDI/firewall configs enforcing managed access points and FIPS-validated crypto; wireless WPA-Enterprise configs; GPO/MDM for session lock/termination. | E39: Estimate - 60 days to remediate Policies and SSP available; attach configs/logs/records as noted
A40: {=IF('SSP - DoD SPRS & FAR and Above'!M172<>"Fully Addressed",'SSP - DoD SPRS & FAR and Above'!E172&" - "&IF('SSP - DoD SPRS & FAR and Above'!I172<>"",'SSP - DoD SPRS & FAR and Above'!I172,'SSP - DoD SPRS & FAR and Above'!J172))} | B40: ISO/CISO | C40: Funded | D40: Export Entra Conditional Access & PIM/PAM approvals; provide VPN/VDI/firewall configs enforcing managed access points and FIPS-validated crypto; wireless WPA-Enterprise configs; GPO/MDM for session lock/termination. | E40: Estimate - 60 days to remediate Policies and SSP available; attach configs/logs/records as noted
...

Sheet Privileged Accounts
A1: Relevant Requirement(s)/Objective(s): | B1: 3.1.5a, 3.1.15a, 3.1.15b, 3.5.3a | C1: Last Reviewed by: | E1: Last Reviewed on:
A2: Account Name | B2: Account Purpose | C2: List of Cloud Services and External Systems Account is Authorized to Access | D2: List of Systems/Subsystems/ Hardware Account is Authorized to Access | E2: List of Software Account is Authorized to Access | F2: Is Account Authorized to Access System Remotely? (Yes/No) | G2: Is Account Authorized to Access System Security Information Remotely? (Yes/No) | H2: List of Privileged Commands Account is Authorized to Remotely Execute | I2: List of Security Information Types Account is Authorized to Remotely Access | J2: List of User(s)/Role(s) of Which Account is Authorized to Act on Behalf | K2: Date Password Last Changed

Sheet Physical Location(s) Info.
A1: Relevant Requirement(s)/ Objective(s): | B1: 3.10.1a, 3.10.5a | C1: Last Reviewed By: | E1: Last Reviewed On:
C2: Location 1 | D2: Location 2 | E2: Location 3 | F2: Location 4 | G2: Location 5
A3: Location Name/Description | C3: California (Hera A&D | West) | D3: California (MSM A&D) | E3: Colorado (Canopy Technologies) | F3: Florida (Hera A&D | East)
A4: Address 1 | C4: 1055 E Francis St | D4: 12660 Magnolia Ave | E4: 8101 Midway Dr | F4: 350 Imperial Blvd
A5: Address 2 | E5: Ste 100
A6: City | C6: Ontario | D6: Riverside | E6: Littleton | F6: Cape Canaveral
A7: State | C7: CA | D7: CA | E7: CO | F7: FL
A8: Country | C8: USA | D8: USA | E8: USA | F8: USA
A9: Postal Code | C9: 91761 | D9: 92503 | E9: 80125 | F9: 32920
A10: Room(s)/Floor(s)/Cage(s)
A11: Accountable Role/Individual
A12: Entry 1 | B12: Location
B13: Physical Access Device
B14: Other Description
A15: Entry 2 | B15: Location
B16: Physical Access Device
B17: Other Description
A18: Entry 3 | B18: Location
B19: Physical Access Device
B20: Other Description
A21: Entry 4 | B21: Location
B22: Physical Access Device
B23: Other Description

Sheet Users Auth. to Access System
A1: Relevant Requirement(s)/ Objective(s): | B1: 3.1.1a, 3.5.1a | C1: Last Reviewed By: | E1: Last Reviewed On:
A2: User ID | B2: Access Authorization Start Date | C2: Access Authorization End Date | D2: Account Authorized By (Name) | E2: User First Name | F2: User Last Name | G2: Organization Name | H2: E-mail Address | I2: User Role(s) | J2: Date Account Created | K2: Date Account Disabled

Sheet User Roles
